Workbook

Sheet Executive Summary
A1: Enterprise AI Capability Map — Life & Health Insurance AI Playbook
A4: 1. AI VISION
A5: To become an AI-native life & health insurer where every underwriting, claims, service and distribution decision is augmented by trusted AI — delivering straight-through operations, hyper-personalised customer engagement, a digitally empowered agency force, and a proactive health partnership with every customer, governed by a Responsible AI framework.
A9: 2. STRATEGIC THEMES
A10: T1 Straight-Through Operations | C10: Automate document-heavy UW, claims and servicing to lift STP and cut unit cost (H1, H4, O1-O4, O16, O17).
A11: T2 Augmented Distribution | C11: Personalisation, NBA, coaching and nudges that raise agent productivity and share of wallet (A1-A21, O5).
A12: T3 Intelligent Health & Risk | C12: Risk scoring, FWA detection and provider analytics that bend the claims cost curve (H2, H3, H5, O7).
A13: T4 Trusted & Governed AI | C13: Responsible AI, model risk management and human-in-the-loop controls as a licence to operate and scale.
A14: T5 Data & Platform Foundations | C14: Customer 360, MDM, document AI platform and enterprise RAG as multipliers for every initiative.
A16: 3. PORTFOLIO & ROADMAP SUMMARY
B17: Health | C17: Operations | D17: Agency | E17: Total
A18: Initiatives | B18: =COUNTIF('AI Portfolio'!$B$5:$B$50,"Health") -> 7 | C18: =COUNTIF('AI Portfolio'!$B$5:$B$50,"Operations") -> 18 | D18: =COUNTIF('AI Portfolio'!$B$5:$B$50,"Agency") -> 21 | E18: =SUM(B18:D18) -> 46
A19: Quick wins | B19: =COUNTIFS('AI Portfolio'!$B$5:$B$50,"Health",'AI Portfolio'!$O$5:$O$50,"Quick Win") -> 0 | C19: =COUNTIFS('AI Portfolio'!$B$5:$B$50,"Operations",'AI Portfolio'!$O$5:$O$50,"Quick Win") -> 5 | D19: =COUNTIFS('AI Portfolio'!$B$5:$B$50,"Agency",'AI Portfolio'!$O$5:$O$50,"Quick Win") -> 8 | E19: =SUM(B19:D19) -> 13
A20: Phase 1 | B20: =COUNTIFS('AI Portfolio'!$B$5:$B$50,"Health",'AI Portfolio'!$O$5:$O$50,"Phase 1") -> 6 | C20: =COUNTIFS('AI Portfolio'!$B$5:$B$50,"Operations",'AI Portfolio'!$O$5:$O$50,"Phase 1") -> 7 | D20: =COUNTIFS('AI Portfolio'!$B$5:$B$50,"Agency",'AI Portfolio'!$O$5:$O$50,"Phase 1") -> 7 | E20: =SUM(B20:D20) -> 20
A21: Phase 2 | B21: =COUNTIFS('AI Portfolio'!$B$5:$B$50,"Health",'AI Portfolio'!$O$5:$O$50,"Phase 2") -> 1 | C21: =COUNTIFS('AI Portfolio'!$B$5:$B$50,"Operations",'AI Portfolio'!$O$5:$O$50,"Phase 2") -> 4 | D21: =COUNTIFS('AI Portfolio'!$B$5:$B$50,"Agency",'AI Portfolio'!$O$5:$O$50,"Phase 2") -> 4 | E21: =SUM(B21:D21) -> 9
A22: Phase 3 | B22: =COUNTIFS('AI Portfolio'!$B$5:$B$50,"Health",'AI Portfolio'!$O$5:$O$50,"Phase 3") -> 0 | C22: =COUNTIFS('AI Portfolio'!$B$5:$B$50,"Operations",'AI Portfolio'!$O$5:$O$50,"Phase 3") -> 2 | D22: =COUNTIFS('AI Portfolio'!$B$5:$B$50,"Agency",'AI Portfolio'!$O$5:$O$50,"Phase 3") -> 2 | E22: =SUM(B22:D22) -> 4
A24: 4. CAPABILITY HEATMAP (initiative count using each AI capability)
A25: AI Capability | B25: Health | C25: Operations | D25: Agency | E25: Total
A26: OCR | B26: =SUMPRODUCT(('AI Portfolio'!$B$5:$B$50="Health")*ISNUMBER(SEARCH("OCR",'AI Portfolio'!$F$5:$F$50&'AI Portfolio'!$G$5:$G$50))) -> 1 | C26: =SUMPRODUCT(('AI Portfolio'!$B$5:$B$50="Operations")*ISNUMBER(SEARCH("OCR",'AI Portfolio'!$F$5:$F$50&'AI Portfolio'!$G$5:$G$50))) -> 2 | D26: =SUMPRODUCT(('AI Portfolio'!$B$5:$B$50="Agency")*ISNUMBER(SEARCH("OCR",'AI Portfolio'!$F$5:$F$50&'AI Portfolio'!$G$5:$G$50))) -> 0 | E26: =SUM(B26:D26) -> 3
A27: Vision | B27: =SUMPRODUCT(('AI Portfolio'!$B$5:$B$50="Health")*ISNUMBER(SEARCH("Vision",'AI Portfolio'!$F$5:$F$50&'AI Portfolio'!$G$5:$G$50))) -> 0 | C27: =SUMPRODUCT(('AI Portfolio'!$B$5:$B$50="Operations")*ISNUMBER(SEARCH("Vision",'AI Portfolio'!$F$5:$F$50&'AI Portfolio'!$G$5:$G$50))) -> 1 | D27: =SUMPRODUCT(('AI Portfolio'!$B$5:$B$50="Agency")*ISNUMBER(SEARCH("Vision",'AI Portfolio'!$F$5:$F$50&'AI Portfolio'!$G$5:$G$50))) -> 0 | E27: =SUM(B27:D27) -> 1
A28: NLP | B28: =SUMPRODUCT(('AI Portfolio'!$B$5:$B$50="Health")*ISNUMBER(SEARCH("NLP",'AI Portfolio'!$F$5:$F$50&'AI Portfolio'!$G$5:$G$50))) -> 1 | C28: =SUMPRODUCT(('AI Portfolio'!$B$5:$B$50="Operations")*ISNUMBER(SEARCH("NLP",'AI Portfolio'!$F$5:$F$50&'AI Portfolio'!$G$5:$G$50))) -> 3 | D28: =SUMPRODUCT(('AI Portfolio'!$B$5:$B$50="Agency")*ISNUMBER(SEARCH("NLP",'AI Portfolio'!$F$5:$F$50&'AI Portfolio'!$G$5:$G$50))) -> 1 | E28: =SUM(B28:D28) -> 5
A29: LLM | B29: =SUMPRODUCT(('AI Portfolio'!$B$5:$B$50="Health")*ISNUMBER(SEARCH("LLM",'AI Portfolio'!$F$5:$F$50&'AI Portfolio'!$G$5:$G$50))) -> 2 | C29: =SUMPRODUCT(('AI Portfolio'!$B$5:$B$50="Operations")*ISNUMBER(SEARCH("LLM",'AI Portfolio'!$F$5:$F$50&'AI Portfolio'!$G$5:$G$50))) -> 7 | D29: =SUMPRODUCT(('AI Portfolio'!$B$5:$B$50="Agency")*ISNUMBER(SEARCH("LLM",'AI Portfolio'!$F$5:$F$50&'AI Portfolio'!$G$5:$G$50))) -> 9 | E29: =SUM(B29:D29) -> 18
A30: RAG | B30: =SUMPRODUCT(('AI Portfolio'!$B$5:$B$50="Health")*ISNUMBER(SEARCH("RAG",'AI Portfolio'!$F$5:$F$50&'AI Portfolio'!$G$5:$G$50))) -> 0 | C30: =SUMPRODUCT(('AI Portfolio'!$B$5:$B$50="Operations")*ISNUMBER(SEARCH("RAG",'AI Portfolio'!$F$5:$F$50&'AI Portfolio'!$G$5:$G$50))) -> 4 | D30: =SUMPRODUCT(('AI Portfolio'!$B$5:$B$50="Agency")*ISNUMBER(SEARCH("RAG",'AI Portfolio'!$F$5:$F$50&'AI Portfolio'!$G$5:$G$50))) -> 2 | E30: =SUM(B30:D30) -> 6
A31: Predictive | B31: =SUMPRODUCT(('AI Portfolio'!$B$5:$B$50="Health")*ISNUMBER(SEARCH("Predictive",'AI Portfolio'!$F$5:$F$50&'AI Portfolio'!$G$5:$G$50))) -> 1 | C31: =SUMPRODUCT(('AI Portfolio'!$B$5:$B$50="Operations")*ISNUMBER(SEARCH("Predictive",'AI Portfolio'!$F$5:$F$50&'AI Portfolio'!$G$5:$G$50))) -> 8 | D31: =SUMPRODUCT(('AI Portfolio'!$B$5:$B$50="Agency")*ISNUMBER(SEARCH("Predictive",'AI Portfolio'!$F$5:$F$50&'AI Portfolio'!$G$5:$G$50))) -> 8 | E31: =SUM(B31:D31) -> 17
A32: Recommendation | B32: =SUMPRODUCT(('AI Portfolio'!$B$5:$B$50="Health")*ISNUMBER(SEARCH("Recommendation",'AI Portfolio'!$F$5:$F$50&'AI Portfolio'!$G$5:$G$50))) -> 1 | C32: =SUMPRODUCT(('AI Portfolio'!$B$5:$B$50="Operations")*ISNUMBER(SEARCH("Recommendation",'AI Portfolio'!$F$5:$F$50&'AI Portfolio'!$G$5:$G$50))) -> 1 | D32: =SUMPRODUCT(('AI Portfolio'!$B$5:$B$50="Agency")*ISNUMBER(SEARCH("Recommendation",'AI Portfolio'!$F$5:$F$50&'AI Portfolio'!$G$5:$G$50))) -> 7 | E32: =SUM(B32:D32) -> 9
A33: Graph | B33: =SUMPRODUCT(('AI Portfolio'!$B$5:$B$50="Health")*ISNUMBER(SEARCH("Graph",'AI Portfolio'!$F$5:$F$50&'AI Portfolio'!$G$5:$G$50))) -> 1 | C33: =SUMPRODUCT(('AI Portfolio'!$B$5:$B$50="Operations")*ISNUMBER(SEARCH("Graph",'AI Portfolio'!$F$5:$F$50&'AI Portfolio'!$G$5:$G$50))) -> 0 | D33: =SUMPRODUCT(('AI Portfolio'!$B$5:$B$50="Agency")*ISNUMBER(SEARCH("Graph",'AI Portfolio'!$F$5:$F$50&'AI Portfolio'!$G$5:$G$50))) -> 0 | E33: =SUM(B33:D33) -> 1
A34: Forecast | B34: =SUMPRODUCT(('AI Portfolio'!$B$5:$B$50="Health")*ISNUMBER(SEARCH("Forecast",'AI Portfolio'!$F$5:$F$50&'AI Portfolio'!$G$5:$G$50))) -> 0 | C34: =SUMPRODUCT(('AI Portfolio'!$B$5:$B$50="Operations")*ISNUMBER(SEARCH("Forecast",'AI Portfolio'!$F$5:$F$50&'AI Portfolio'!$G$5:$G$50))) -> 0 | D34: =SUMPRODUCT(('AI Portfolio'!$B$5:$B$50="Agency")*ISNUMBER(SEARCH("Forecast",'AI Portfolio'!$F$5:$F$50&'AI Portfolio'!$G$5:$G$50))) -> 1 | E34: =SUM(B34:D34) -> 1
A35: Optimization | B35: =SUMPRODUCT(('AI Portfolio'!$B$5:$B$50="Health")*ISNUMBER(SEARCH("Optimization",'AI Portfolio'!$F$5:$F$50&'AI Portfolio'!$G$5:$G$50))) -> 0 | C35: =SUMPRODUCT(('AI Portfolio'!$B$5:$B$50="Operations")*ISNUMBER(SEARCH("Optimization",'AI Portfolio'!$F$5:$F$50&'AI Portfolio'!$G$5:$G$50))) -> 2 | D35: =SUMPRODUCT(('AI Portfolio'!$B$5:$B$50="Agency")*ISNUMBER(SEARCH("Optimization",'AI Portfolio'!$F$5:$F$50&'AI Portfolio'!$G$5:$G$50))) -> 2 | E35: =SUM(B35:D35) -> 4
A36: Agentic | B36: =SUMPRODUCT(('AI Portfolio'!$B$5:$B$50="Health")*ISNUMBER(SEARCH("Agentic",'AI Portfolio'!$F$5:$F$50&'AI Portfolio'!$G$5:$G$50))) -> 0 | C36: =SUMPRODUCT(('AI Portfolio'!$B$5:$B$50="Operations")*ISNUMBER(SEARCH("Agentic",'AI Portfolio'!$F$5:$F$50&'AI Portfolio'!$G$5:$G$50))) -> 1 | D36: =SUMPRODUCT(('AI Portfolio'!$B$5:$B$50="Agency")*ISNUMBER(SEARCH("Agentic",'AI Portfolio'!$F$5:$F$50&'AI Portfolio'!$G$5:$G$50))) -> 0 | E36: =SUM(B36:D36) -> 1
A38: 5. AI CAPABILITY → TYPICAL USE CASES
A39: Capability | B39: Typical use cases
A40: OCR / Document AI | B40: Document digitization, KYC, claims intake
A41: Computer Vision | B41: ID verification, damage/medical image assessment, fraud
A42: NLP | B42: Medical summaries, underwriting notes, complaints, voice analytics
A43: LLM (GenAI) | B43: Copilots, Q&A, document generation, coaching, summarization
A44: RAG | B44: Policy/UW guideline retrieval, enterprise knowledge assistant
A45: Predictive ML | B45: Lapse, propensity, churn, renewals, risk scoring
A46: Recommendation Engine | B46: Next Best Action, cross-sell, wellness nudges
A47: Graph AI | B47: Fraud rings, provider networks, referral mining
A48: Time-Series Forecasting | B48: Renewals, claims volumes, workforce demand
...

Sheet AI Portfolio
A1: AI Portfolio — Master Table (46 initiatives: 7 Health / 18 Operations / 21 Agency )
A4: ID | B4: Domain | C4: AI Initiative | D4: Strategic Goal | E4: Business Problem | F4: AI Capability | G4: GenAI/ML Approach | H4: Data Required | I4: Core Tables | J4: Expected Output | K4: Primary Users | L4: KPIs | M4: Business Value | N4: Implementation Complexity | O4: Phase | P4: Industry Maturity | Q4: Value Score (1-5) | R4: Complexity Score (1-5)
A5: H1 | B5: Health | C5: AI-Powered Document Digitization | D5: Digitise medical information end-to-end (domain goal ) | E5: Medical reports are manual and slow | F5: OCR + GenAI summarization | G5: OCR, Document AI, Medical NLP, LLM summarization | H5: Medical reports, lab reports, prescriptions, discharge summaries | I5: Claims, Policies, Customers, Medical Documents, Providers | J5: Structured medical record and summary ; ICD codes, risk indicators | K5: Underwriters, Claims Officers, Medical Team | L5: Turnaround time, extraction accuracy, straight-through processing rate | M5: Faster processing and reduced manual effort across UW and claims | N5: Medium | O5: Phase 1 | P5: High (widely adopted) | Q5: 5 | R5: 3
A6: H2 | B6: Health | C6: GenAI Real-Time FWA Detection | D6: Reduce fraud and cost leakage in health claims | E6: Fraudulent or duplicate claims inflate claims cost | F6: Fraud detection models + LLM reasoning + Graph AI | G6: Supervised fraud classification, anomaly detection, duplicate-claim matching, LLM case reasoning | H6: Claims, provider history, diagnosis codes, billing data | I6: Claims, Claim Line Items, Providers, Diagnoses, Procedures, Investigations | J6: Fraud score, suspicious claims investigation queue | K6: SIU / Fraud Investigators, Claims Managers | L6: Fraud detection rate, false-positive rate, recovered amount, duplicate-claim catch rate | M6: Direct claims-cost avoidance and loss-ratio improvement | N6: High | O6: Phase 1 | P6: Medium-High | Q6: 5 | R6: 4
A7: H3 | B7: Health | C7: ML-Powered Predictive Risk Scoring | D7: Assess claim and health risk consistently at scale | E7: Difficult to assess claim or health risk manually | F7: Predictive ML risk models | G7: Risk prediction / classification models (gradient boosting), calibration, explainability (SHAP) | H7: Medical history, lifestyle data, demographics | I7: Customers, Claims, Medical Documents, Policies, Health Assessments | J7: Risk score (Low/Medium/High) with drivers | K7: Underwriters, Claims Assessors, Medical Team | L7: Model AUC/calibration, referral precision, downstream TAT | M7: Consistent risk selection and faster decisions | N7: Medium | O7: Phase 1 | P7: High | Q7: 4 | R7: 3
A8: H4 | B8: Health | C8: Intelligent Rule Engine & Decision Automation | D8: Automate approval decisions for claims and underwriting | E8: Manual approval decisions are slow and inconsistent | F8: Rule engine + AI recommendations | G8: Business-rules engine integrated with ML classification scores; escalation thresholds; audit trail | H8: Claims, underwriting rules, policies | I8: Claims, Policies, Benefits, Underwriting Decisions, Rules Repository | J8: Approve / Reject / Escalate recommendation with rationale | K8: Claims Officers, Underwriters, Ops Managers | L8: Auto-decision rate, override rate, decision TAT, leakage | M8: Straight-through decisions with human-in-the-loop for exceptions | N8: Medium-High | O8: Phase 1 | P8: High | Q8: 5 | R8: 4
A9: H5 | B9: Health | C9: AI Portfolio-Level Claims Intelligence & Provider Analytics | D9: Create visibility into provider performance and treatment patterns | E9: Limited visibility into provider performance | F9: Claims analytics + Clustering | G9: Clustering/segmentation of providers, benchmarking analytics, fraud-trend mining, cost-leakage analytics | H9: Claims, hospital data, provider data, treatment/procedure codes | I9: Claims, Providers, Provider Networks, Procedures, Tariffs | J9: Provider scorecards, fraud trends, treatment patterns, cost leakage dashboard | K9: Provider Management, Claims Managers, Health Economics Team | L9: Cost per episode vs benchmark, provider score adoption, leakage identified | M9: Better provider negotiation and network steering | N9: Medium | O9: Phase 1 | P9: Medium-High | Q9: 4 | R9: 3
A10: H6 | B10: Health | C10: GTM (Go-To-Market) Rollout | D10: Commercial rollout of Health AI capabilities | E10: Operational readiness required to deploy AI into live health business | F10: Program milestone: operational readiness (process, people, controls) | G10: N/A (deployment milestone) — model operationalisation, monitoring setup, adoption tooling | H10: Business processes, SOPs, training material, deployment checklists | I10: Workflow Tasks, Knowledge Articles, Org Structure | J10: Deployment plan and live rollout | K10: Program Office, Health Business Owners, Ops, IT | L10: Go-live milestones met, adoption rate, incident rate post-launch | M10: Converts Health AI builds into realised business value | N10: Medium | O10: Phase 1 | P10: N/A (program phase) | Q10: 3 | R10: 3
A11: H7 | B11: Health | C11: MVP 2 — Expanded Health AI Capabilities | D11: Second implementation phase extending Health AI scope | E11: Initial MVP covers core scope; expanded datasets and features needed | F11: Program milestone: expanded AI capabilities on additional datasets | G11: Iteration on H1-H5 models: added data sources, advanced features, wider claim types | H11: Additional datasets : expanded document types, external health data | I11: Claims, Medical Documents, Providers, External Data Registry | J11: Advanced AI features across the Health stack | K11: Program Office, Health Business Owners, Data Science | L11: Scope-expansion milestones, incremental STP/fraud KPIs vs MVP1 baseline | M11: Compounding value on the MVP foundation | N11: Medium-High | O11: Phase 2 | P11: N/A (program phase) | Q11: 3 | R11: 4
A12: O1 | B12: Operations | C12: Ingest, Extract & Summarize Medical Information (Life & Health) | D12: Convert PDFs into structured information | E12: Operational teams re-key data from unstructured medical PDFs | F12: OCR + Document AI + Medical NLP | G12: OCR, layout parsing, entity extraction, LLM summarization | H12: Medical PDFs, attachments, scanned reports | I12: Medical Documents, Claims, Applications, Customers | J12: Medical summary ; structured fields with confidence scores | K12: Operations Staff, Underwriting Support, Claims Support | L12: Extraction accuracy, docs auto-processed %, re-key effort saved | M12: Shared extraction service feeding UW and claims | N12: Low-Medium | O12: Quick Win | P12: High | Q12: 4 | R12: 2
A13: O2 | B13: Operations | C13: Structure Unstructured Data for Underwriting | D13: Extract underwriting attributes into a structured profile | E13: UW-relevant attributes are buried in documents and free text | F13: Document AI + NLP | G13: Attribute extraction models, medical/financial entity recognition, normalization to UW schema | H13: Application forms, medical evidence, financial documents | I13: Applications, Underwriting Decisions, Medical Documents, Customers | J13: Structured underwriting profile | K13: Underwriters, New Business Ops | L13: Profile completeness, extraction accuracy, UW prep time | M13: Feeds indicative UW decisions (O4) and pricing (O8) | N13: Medium | O13: Quick Win | P13: High | Q13: 4 | R13: 3
A14: O2B | B14: Operations | C14: Automated KYC Verification | D14: Automate identity verification | E14: Manual KYC checks slow onboarding and create compliance risk | F14: OCR + Computer Vision + Screening rules | G14: ID document classification, face/ID match, watchlist screening, entity resolution | H14: Identity documents, proof of address, sanctions/PEP watchlists | I14: Customers, KYC Records, Documents, Watchlists | J14: Verified customer ; KYC status and exception queue | K14: New Business Ops, Compliance | L14: Onboarding TAT, KYC exception rate, compliance findings | M14: Faster onboarding with lower compliance risk | N14: Low | O14: Quick Win | P14: High | Q14: 3 | R14: 2
A15: O3 | B15: Operations | C15: GenAI Proactive Data-Quality Detection | D15: Detect missing or incorrect data automatically | E15: Poor data quality undermines decisions and downstream AI | F15: ML anomaly detection + Rule mining | G15: DQ rule learning, outlier detection, completeness/consistency monitors, entity resolution | H15: Core system extracts, customer master, policy master | I15: Customers, Policies, Claims, Agents, Reference Data | J15: Data quality alerts ; DQ dashboard and remediation queues | K15: Data Office, Ops Teams, IT | L15: DQ score trend, duplicate rate, issues auto-detected % | M15: Foundation multiplier for every other initiative | N15: Low-Medium | O15: Quick Win | P15: Medium | Q15: 3 | R15: 2
A16: O4 | B16: Operations | C16: Generate Indicative Decisions for Underwriters | D16: Recommend underwriting outcomes | E16: Manual UW review constrains capacity and consistency | F16: Predictive ML + Rules + LLM evidence review | G16: Classification models (Approve/Decline/Review), rules integration, LLM-assisted evidence summarisation | H16: Structured UW profile (O2), medical evidence, application data | I16: Applications, Underwriting Decisions, Medical Documents, Products | J16: Approve / Decline / Review recommendation | K16: Underwriters, Chief Underwriter | L16: Auto-decision rate, UW TAT, decision consistency, slippage | M16: Higher STP issuance and capacity uplift | N16: High | O16: Phase 1 | P16: High | Q16: 5 | R16: 4
... A50: A21 | B50: Agency | C50: Action-Oriented Real-Time Performance Monitoring | D50: Recommend leadership actions from performance data | E50: Dashboards show what happened but not what to do | F50: Predictive ML + LLM recommendations | G50: Driver analysis, intervention recommendation models, LLM coaching-plan generation (PruAction-style) | H50: Performance data (A20), profiling (A13), intervention outcomes | I50: Agents, Performance Records, Targets, Recommendations | J50: Coaching and intervention plans | K50: Agency Leaders, Unit Managers | L50: Intervention success rate, coached-cohort productivity delta, active-agent ratio | M50: Prudential PruAction benchmark: GenAI performance management | N50: Medium | O50: Phase 1 | P50: Medium-High | Q50: 4 | R50: 3

Sheet Health AI
A1: Health AI — Detailed Breakdown (7 listed in source (header states 8) initiatives)
A4: H1 — AI-Powered Document Digitization
A5: Strategic Goal | B5: Digitise medical information end-to-end (domain goal per PDF)
A6: Business Problem | B6: Medical reports are manual and slow
A7: AI Capability | B7: OCR + GenAI summarization
A8: GenAI/ML Approach | B8: OCR, Document AI, Medical NLP, LLM summarization
A9: Data Required | B9: Medical reports, lab reports, prescriptions, discharge summaries
A10: Core Tables | B10: Claims, Policies, Customers, Medical Documents, Providers
A11: Expected Output | B11: Structured medical record and summary ; ICD codes, risk indicators
A12: Primary Users | B12: Underwriters, Claims Officers, Medical Team
A13: KPIs | B13: Turnaround time, extraction accuracy, straight-through processing rate
A14: Business Value | B14: Faster processing and reduced manual effort across UW and claims
A15: Complexity | B15: Medium
A16: Industry Maturity | B16: High (widely adopted)
A17: Roadmap Phase | B17: Phase 1
A19: H2 — GenAI Real-Time FWA Detection
A20: Strategic Goal | B20: Reduce fraud and cost leakage in health claims
A21: Business Problem | B21: Fraudulent or duplicate claims inflate claims cost
A22: AI Capability | B22: Fraud detection models + LLM reasoning + Graph AI
A23: GenAI/ML Approach | B23: Supervised fraud classification, anomaly detection, duplicate-claim matching, LLM case reasoning
A24: Data Required | B24: Claims, provider history, diagnosis codes, billing data
A25: Core Tables | B25: Claims, Claim Line Items, Providers, Diagnoses, Procedures, Investigations
A26: Expected Output | B26: Fraud score, suspicious claims investigation queue
A27: Primary Users | B27: SIU / Fraud Investigators, Claims Managers
A28: KPIs | B28: Fraud detection rate, false-positive rate, recovered amount, duplicate-claim catch rate
A29: Business Value | B29: Direct claims-cost avoidance and loss-ratio improvement
A30: Complexity | B30: High
A31: Industry Maturity | B31: Medium-High
A32: Roadmap Phase | B32: Phase 1
A34: H3 — ML-Powered Predictive Risk Scoring
A35: Strategic Goal | B35: Assess claim and health risk consistently at scale
A36: Business Problem | B36: Difficult to assess claim or health risk manually
A37: AI Capability | B37: Predictive ML risk models
A38: GenAI/ML Approach | B38: Risk prediction / classification models (gradient boosting), calibration, explainability (SHAP)
A39: Data Required | B39: Medical history, lifestyle data, demographics
A40: Core Tables | B40: Customers, Claims, Medical Documents, Policies, Health Assessments
A41: Expected Output | B41: Risk score (Low/Medium/High) with drivers
A42: Primary Users | B42: Underwriters, Claims Assessors, Medical Team
A43: KPIs | B43: Model AUC/calibration, referral precision, downstream TAT
A44: Business Value | B44: Consistent risk selection and faster decisions
...

Sheet Operations AI
A1: Operations AI — Detailed Breakdown (18 listed in source (rows 1-17 + 2B) initiatives)
A4: O1 — Ingest, Extract & Summarize Medical Information (Life & Health)
A5: Strategic Goal | B5: Convert PDFs into structured information
A6: Business Problem | B6: Operational teams re-key data from unstructured medical PDFs
A7: AI Capability | B7: OCR + Document AI + Medical NLP
A8: GenAI/ML Approach | B8: OCR, layout parsing, entity extraction, LLM summarization
A9: Data Required | B9: Medical PDFs, attachments, scanned reports
A10: Core Tables | B10: Medical Documents, Claims, Applications, Customers
A11: Expected Output | B11: Medical summary ; structured fields with confidence scores
A12: Primary Users | B12: Operations Staff, Underwriting Support, Claims Support
A13: KPIs | B13: Extraction accuracy, docs auto-processed %, re-key effort saved
A14: Business Value | B14: Shared extraction service feeding UW and claims
A15: Complexity | B15: Low-Medium
A16: Industry Maturity | B16: High
A17: Roadmap Phase | B17: Quick Win
A19: O2 — Structure Unstructured Data for Underwriting
A20: Strategic Goal | B20: Extract underwriting attributes into a structured profile
A21: Business Problem | B21: UW-relevant attributes are buried in documents and free text
A22: AI Capability | B22: Document AI + NLP
A23: GenAI/ML Approach | B23: Attribute extraction models, medical/financial entity recognition, normalization to UW schema
A24: Data Required | B24: Application forms, medical evidence, financial documents
A25: Core Tables | B25: Applications, Underwriting Decisions, Medical Documents, Customers
A26: Expected Output | B26: Structured underwriting profile
A27: Primary Users | B27: Underwriters, New Business Ops
A28: KPIs | B28: Profile completeness, extraction accuracy, UW prep time
A29: Business Value | B29: Feeds indicative UW decisions (O4) and pricing (O8)
A30: Complexity | B30: Medium
A31: Industry Maturity | B31: High
A32: Roadmap Phase | B32: Quick Win
A34: O2B — Automated KYC Verification
A35: Strategic Goal | B35: Automate identity verification
A36: Business Problem | B36: Manual KYC checks slow onboarding and create compliance risk
A37: AI Capability | B37: OCR + Computer Vision + Screening rules
A38: GenAI/ML Approach | B38: ID document classification, face/ID match, watchlist screening, entity resolution
A39: Data Required | B39: Identity documents, proof of address, sanctions/PEP watchlists
A40: Core Tables | B40: Customers, KYC Records, Documents, Watchlists
A41: Expected Output | B41: Verified customer ; KYC status and exception queue
A42: Primary Users | B42: New Business Ops, Compliance
A43: KPIs | B43: Onboarding TAT, KYC exception rate, compliance findings
A44: Business Value | B44: Faster onboarding with lower compliance risk
...

Sheet Agency AI
A1: Agency AI — Detailed Breakdown (21 initiatives)
A4: A1 — Hyper-Personalized Product Offering
A5: Strategic Goal | B5: Sell the right product to each customer
A6: Business Problem | B6: Generic offers ignore individual needs and context
A7: AI Capability | B7: Recommendation engine + Predictive ML
A8: GenAI/ML Approach | B8: Product recommenders, propensity models, coverage-gap analytics
A9: Data Required | B9: Customer 360, holdings, life events, demographics
A10: Core Tables | B10: Customers, Policies, Products, Events, Recommendations
A11: Expected Output | B11: Personalised recommendations
A12: Primary Users | B12: Agents, Bancassurance RMs
A13: KPIs | B13: Offer acceptance rate, conversion, APE uplift
A14: Business Value | B14: Core revenue engine for personalised selling
A15: Complexity | B15: Medium
A16: Industry Maturity | B16: High
A17: Roadmap Phase | B17: Phase 1
A19: A2 — Hyper-Personalized Campaigning & Lead Generation
A20: Strategic Goal | B20: Improve marketing ROI
A21: Business Problem | B21: Broad campaigns waste budget on unlikely converters
A22: AI Capability | B22: Predictive ML + Optimization + GenAI content
A23: GenAI/ML Approach | B23: Response/uplift models, segment targeting, budget optimisation, personalised content variants
A24: Data Required | B24: Campaign history, responses, segments, channel costs, content assets
A25: Core Tables | B25: Campaigns, Segments, Customers, Responses, Content Library
A26: Expected Output | B26: Target customer lists ; optimised campaign plans
A27: Primary Users | B27: Marketing, Distribution Campaigns
A28: KPIs | B28: Campaign ROI, response rate, CPA
A29: Business Value | B29: Higher marketing ROI with personalisation at scale
A30: Complexity | B30: Medium
A31: Industry Maturity | B31: High
A32: Roadmap Phase | B32: Phase 1
A34: A3 — Pre-Sales Intelligence Engine
A35: Strategic Goal | B35: Prepare agents before meetings
A36: Business Problem | B36: Agents walk into meetings without a synthesised customer view
A37: AI Capability | B37: LLM + Customer analytics
A38: GenAI/ML Approach | B38: LLM-generated customer briefings from Customer 360, holdings, gaps and talking points
A39: Data Required | B39: Customer 360, holdings, interactions, needs data
A40: Core Tables | B40: Customers, Policies, Interactions, FNA Records
A41: Expected Output | B41: Customer briefing before every meeting
A42: Primary Users | B42: Agents, Agency Leaders
A43: KPIs | B43: Briefing usage rate, meeting-to-proposal conversion, case size
A44: Business Value | B44: Better conversations, higher conversion
...

Sheet Data Requirements
A1: Data Requirements by Initiative
A4: ID | B4: Initiative | C4: Source Systems | D4: Core Tables | E4: Master Data | F4: Events | G4: External Data | H4: Document Data
A5: H1 | B5: AI-Powered Document Digitization | C5: • Policy Administration System • Claims Management System • CRM / Customer Master (MDM) • Document Management (ECM) • Provider Network System | D5: Claims, Policies, Customers, Medical Documents, Providers | E5: Customer, Provider | F5: • Claim lifecycle events | G5: — | H5: Medical reports, Discharge summaries, Prescriptions, Lab reports
A6: H2 | B6: GenAI Real-Time FWA Detection | C6: • Claims Management System • Provider Network System | D6: Claims, Claim Line Items, Providers, Diagnoses, Procedures, Investigations | E6: Provider | F6: • Claim lifecycle events | G6: — | H6: Identity documents, Provider bills/invoices
A7: H3 | B7: ML-Powered Predictive Risk Scoring | C7: • Policy Administration System • Claims Management System • CRM / Customer Master (MDM) • Document Management (ECM) | D7: Customers, Claims, Medical Documents, Policies, Health Assessments | E7: Customer | F7: • Claim lifecycle events | G7: — | H7: —
A8: H4 | B8: Intelligent Rule Engine & Decision Automation | C8: • Policy Administration System • Claims Management System | D8: Claims, Policies, Benefits, Underwriting Decisions, Rules Repository | E8: Customer, Product | F8: • Claim lifecycle events | G8: — | H8: —
A9: H5 | B9: AI Portfolio-Level Claims Intelligence & Provider Analytics | C9: • Claims Management System • Provider Network System | D9: Claims, Providers, Provider Networks, Procedures, Tariffs | E9: Provider | F9: • Claim lifecycle events | G9: — | H9: Identity documents
A10: H6 | B10: GTM (Go-To-Market) Rollout | C10: • Learning Management System • Knowledge Base / Intranet | D10: Workflow Tasks, Knowledge Articles, Org Structure | E10: Customer, Product | F10: • Policy lifecycle events | G10: — | H10: SOPs & circulars
A11: H7 | B11: MVP 2 — Expanded Health AI Capabilities | C11: • Claims Management System • Document Management (ECM) • Provider Network System | D11: Claims, Medical Documents, Providers, External Data Registry | E11: Provider | F11: • Claim lifecycle events | G11: — | H11: —
A12: O1 | B12: Ingest, Extract & Summarize Medical Information (Life & Health) | C12: • Policy Administration System • Claims Management System • CRM / Customer Master (MDM) • Document Management (ECM) | D12: Medical Documents, Claims, Applications, Customers | E12: Customer | F12: • Claim lifecycle events | G12: — | H12: —
A13: O2 | B13: Structure Unstructured Data for Underwriting | C13: • Policy Administration System • CRM / Customer Master (MDM) • Document Management (ECM) | D13: Applications, Underwriting Decisions, Medical Documents, Customers | E13: Customer | F13: • Policy lifecycle events | G13: — | H13: Identity documents, Application/claim forms
A14: O2B | B14: Automated KYC Verification | C14: • CRM / Customer Master (MDM) • Document Management (ECM) • Compliance / Screening Systems | D14: Customers, KYC Records, Documents, Watchlists | E14: Customer | F14: • Policy lifecycle events | G14: Sanctions / PEP watchlists | H14: Identity documents
A15: O3 | B15: GenAI Proactive Data-Quality Detection | C15: • Policy Administration System • Claims Management System • CRM / Customer Master (MDM) • Agency Portal / SFA | D15: Customers, Policies, Claims, Agents, Reference Data | E15: Customer, Agent, Reference/Code sets | F15: • Claim lifecycle events | G15: — | H15: —
... A21: O9 | B21: Proactive Renewals | C21: • Policy Administration System • CRM / Customer Master (MDM) • Agency Portal / SFA • Finance / Payments Platform • Contact Centre / Telephony | D21: Policies, Payments, Customers, Agents, Interactions | E21: Customer, Agent | F21: • Premium/payment events • Service interaction events | G21: — | H21: —
A22: O10 | B22: Market-Based / Lifetime-Based Pricing & Elasticity Models | D22: Products, Rates, Quotes, External Market Data | E22: Product | F22: • Policy lifecycle events | G22: — | H22: —
A23: O11 | B23: Customer Self-Service Assistant (Chatbot) | C23: • Policy Administration System • CRM / Customer Master (MDM) • Contact Centre / Telephony • Knowledge Base / Intranet | D23: Customers, Policies, Knowledge Articles, Service Requests, Interactions | E23: Customer | F23: • Service interaction events | G23: — | H23: —
A24: O12 | B24: Smart Routing | C24: • Claims Management System | D24: Service Requests, Claims, Workflow Tasks, Rosters | E24: Customer, Product | F24: • Claim lifecycle events | G24: — | H24: —
A25: O13 | B25: GenAI Real-Time Coaching | C25: • Contact Centre / Telephony • Knowledge Base / Intranet | D25: Interactions, Knowledge Articles, QA Scores | E25: Customer, Product | F25: • Service interaction events • Call events | G25: — | H25: —
A26: O14 | B26: Servicing Staff Support AI | C26: • Policy Administration System • Document Management (ECM) • Knowledge Base / Intranet | D26: Service Requests, Policies, Knowledge Articles, Documents, Templates | E26: Customer, Product | F26: • Policy lifecycle events | G26: — | H26: SOPs & circulars
A27: O15 | B27: Predictive Customer Behaviour & Proactive Servicing | C27: • Policy Administration System • CRM / Customer Master (MDM) • Finance / Payments Platform • Contact Centre / Telephony | D27: Customers, Policies, Payments, Interactions, Digital Events | E27: Customer | F27: • Premium/payment events • Service interaction events • Digital/clickstream events | G27: — | H27: —
A28: O16 | B28: AI-Enabled Claims Adjudication | C28: • Policy Administration System • Claims Management System • Document Management (ECM) • Provider Network System | D28: Claims, Claim Line Items, Policies, Benefits, Providers, Tariffs | E28: Provider | F28: • Claim lifecycle events | G28: — | H28: Application/claim forms, Provider bills/invoices
A29: O17 | B29: Guided Claims | C29: • Claims Management System • Document Management (ECM) • Knowledge Base / Intranet | D29: Claims, Workflow Tasks, Knowledge Articles, Documents | E29: Customer, Product | F29: • Claim lifecycle events | G29: — | H29: UW/ops manuals
A30: A1 | B30: Hyper-Personalized Product Offering | C30: • Policy Administration System • CRM / Customer Master (MDM) | D30: Customers, Policies, Products, Events, Recommendations | E30: Customer, Product | F30: • Life events | G30: — | H30: —
A31: A2 | B31: Hyper-Personalized Campaigning & Lead Generation | C31: • CRM / Customer Master (MDM) • Campaign / Martech Platform • Learning Management System | D31: Campaigns, Segments, Customers, Responses, Content Library | E31: Customer | F31: • Campaign response events | G31: — | H31: —
A32: A3 | B32: Pre-Sales Intelligence Engine | C32: • Policy Administration System • CRM / Customer Master (MDM) • Contact Centre / Telephony | D32: Customers, Policies, Interactions, FNA Records | E32: Customer | F32: • Service interaction events | G32: — | H32: —
A33: A4 | B33: Automated Funnel Management | C33: • Policy Administration System • Agency Portal / SFA | D33: Leads, Sales Activity, Agents, Policies | E33: Agent | F33: • Lead status events | G33: — | H33: —
A34: A5 | B34: Investment Earning Simulator | C34: • CRM / Customer Master (MDM) | D34: Products, Rates, Funds, Quotes, Illustrations | E34: Product | F34: • Policy lifecycle events | G34: — | H34: Application/claim forms
... A50: A21 | B50: Action-Oriented Real-Time Performance Monitoring | C50: • Agency Portal / SFA | D50: Agents, Performance Records, Targets, Recommendations | E50: Agent | F50: • Policy lifecycle events | G50: — | H50: Application/claim forms

Sheet ML Models
A1: ML / AI Model Types by Initiative (● = core, blank = not required)
A4: ID | B4: Initiative | C4: Classification | D4: Regression | E4: Recommendation | F4: Clustering | G4: NLP | H4: Computer Vision | I4: GenAI (LLM) | J4: RAG | K4: Agentic AI | L4: Primary Modeling Notes
A5: H1 | B5: AI-Powered Document Digitization | G5: ● | H5: ● | I5: ● | L5: OCR, Document AI, Medical NLP, LLM summarization
A6: H2 | B6: GenAI Real-Time FWA Detection | C6: ● | I6: ● | L6: Supervised fraud classification, anomaly detection, duplicate-claim matching, LLM case reasoning
A7: H3 | B7: ML-Powered Predictive Risk Scoring | C7: ● | L7: Risk prediction / classification models (gradient boosting), calibration, explainability (SHAP)
A8: H4 | B8: Intelligent Rule Engine & Decision Automation | C8: ● | E8: ● | L8: Business-rules engine integrated with ML classification scores; escalation thresholds; audit trail
A9: H5 | B9: AI Portfolio-Level Claims Intelligence & Provider Analytics | C9: ● | F9: ● | L9: Clustering/segmentation of providers, benchmarking analytics, fraud-trend mining, cost-leakage analytics
A10: H6 | B10: GTM (Go-To-Market) Rollout | L10: N/A (deployment milestone) — model operationalisation, monitoring setup, adoption tooling
A11: H7 | B11: MVP 2 — Expanded Health AI Capabilities | L11: Iteration on H1-H5 models: added data sources, advanced features, wider claim types
A12: O1 | B12: Ingest, Extract & Summarize Medical Information (Life & Health) | G12: ● | H12: ● | I12: ● | L12: OCR, layout parsing, entity extraction, LLM summarization
A13: O2 | B13: Structure Unstructured Data for Underwriting | G13: ● | L13: Attribute extraction models, medical/financial entity recognition, normalization to UW schema
A14: O2B | B14: Automated KYC Verification | C14: ● | H14: ● | L14: ID document classification, face/ID match, watchlist screening, entity resolution
A15: O3 | B15: GenAI Proactive Data-Quality Detection | I15: ● | L15: DQ rule learning, outlier detection, completeness/consistency monitors, entity resolution
A16: O4 | B16: Generate Indicative Decisions for Underwriters | C16: ● | E16: ● | I16: ● | L16: Classification models (Approve/Decline/Review), rules integration, LLM-assisted evidence summarisation
A17: O5 | B17: Generate Indicative Decisions for Agents / Banca RMs | C17: ● | E17: ● | L17: Next-action recommenders, product propensity models, prioritisation scoring
A18: O6 | B18: Helpdesk Chatbot for Agents / Banca RMs | I18: ● | J18: ● | L18: RAG over SOPs, product documents and IT knowledge base; permissioned answers with citations
A19: O7 | B19: Identify High-Value Distribution Partners / Clients / Cases | C19: ● | F19: ● | L19: Partner value scoring, clustering, benchmark analytics
A20: O8 | B20: Technical Pricing | E20: ● | L20: Risk-cost models (GLM/GBM), elasticity modelling, factor optimisation with actuarial governance
A21: O9 | B21: Proactive Renewals | C21: ● | E21: ● | L21: Renewal-propensity classification, time-to-event models, intervention uplift
A22: O10 | B22: Market-Based / Lifetime-Based Pricing & Elasticity Models | E22: ● | L22: Competitive-position models, customer-lifetime-value (CLV) models, demand elasticity, constrained pricing optimization with guardrails
A23: O11 | B23: Customer Self-Service Assistant (Chatbot) | G23: ● | I23: ● | J23: ● | L23: Conversational assistant with policy-context retrieval, guarded transaction flows, handover to human
A24: O12 | B24: Smart Routing | C24: ● | L24: Case classification, complexity scoring, skill-based routing optimisation
A25: O13 | B25: GenAI Real-Time Coaching | E25: ● | G25: ● | I25: ● | L25: Live transcription, intent/sentiment detection, real-time prompt suggestions
A26: O14 | B26: Servicing Staff Support AI | G26: ● | I26: ● | J26: ● | L26: Case-context summarisation, guided procedures, draft correspondence, next-step suggestions
A27: O15 | B27: Predictive Customer Behaviour & Proactive Servicing | C27: ● | L27: Behaviour prediction models (lapse, complaint, contact, claim propensity), feature-store based
A28: O16 | B28: AI-Enabled Claims Adjudication | C28: ● | E28: ● | K28: ● | L28: Payable/refer classification, benefit-rule application, anomaly screens, agent orchestration with human-in-the-loop
A29: O17 | B29: Guided Claims | G29: ● | I29: ● | J29: ● | L29: Guided workflow generation, checklist automation, contextual guidance from claims manuals (RAG)
A30: A1 | B30: Hyper-Personalized Product Offering | C30: ● | E30: ● | J30: ● | L30: Product recommenders, propensity models, coverage-gap analytics
A31: A2 | B31: Hyper-Personalized Campaigning & Lead Generation | E31: ● | F31: ● | I31: ● | L31: Response/uplift models, segment targeting, budget optimisation, personalised content variants
A32: A3 | B32: Pre-Sales Intelligence Engine | I32: ● | L32: LLM-generated customer briefings from Customer 360, holdings, gaps and talking points
A33: A4 | B33: Automated Funnel Management | K33: ● | L33: Stage-conversion models, stall detection, automated follow-up orchestration
A34: A5 | B34: Investment Earning Simulator | I34: ● | L34: Monte-Carlo/deterministic projection engines with plain-language LLM explanations, compliance-guarded
A35: A6 | B35: AI "Get Smart" / Pre-Pitch Support | E35: ● | G35: ● | I35: ● | J35: ● | L35: Pitch generation from customer context + product library, objection-handling suggestions
A36: A7 | B36: Value-Based Segmentation & Prioritization | F36: ● | L36: Lifetime-value models, profitability clustering, migration analysis
A37: A8 | B37: In-the-Moment Live Sales Coach | G37: ● | I37: ● | L37: Live conversation analysis, next-talking-point suggestions, compliance prompts
A38: A9 | B38: Proactive Servicing & Admin Automation AI | C38: ● | E38: ● | L38: Issue-propensity models (payment failure, service need), outreach recommendations
A39: A10 | B39: Automated Reactive Servicing | C39: ● | I39: ● | L39: Request classification, suggested resolutions, auto-drafted responses with approval
A40: A11 | B40: AI Nudges for Agents (Key Actions) | E40: ● | L40: Event-triggered nudge engine with prioritisation and fatigue control
A41: A12 | B41: Next Best Action & Goal-Planning AI | E41: ● | L41: NBA models, goal-gap analytics, prioritised task planning
A42: A13 | B42: AI-Enabled Agent Profiling | F42: ● | L42: Skill/behaviour profiling, archetype clustering, gap-to-top-performer analysis
...

Sheet Business KPIs
A1: Business KPI Impact by Initiative (High / Medium / —)
A4: ID | B4: Initiative | C4: Revenue Uplift | D4: Claims Reduction | E4: Productivity | F4: Customer Satisfaction | G4: Agent Productivity | H4: Cost Reduction | I4: Primary KPIs
A5: H1 | B5: AI-Powered Document Digitization | C5: — | D5: — | E5: High | F5: — | G5: — | H5: Medium | I5: Turnaround time, extraction accuracy, straight-through processing rate
A6: H2 | B6: GenAI Real-Time FWA Detection | C6: — | D6: High | E6: — | F6: — | G6: — | H6: — | I6: Fraud detection rate, false-positive rate, recovered amount, duplicate-claim catch rate
A7: H3 | B7: ML-Powered Predictive Risk Scoring | C7: High | D7: — | E7: High | F7: — | G7: — | H7: — | I7: Model AUC/calibration, referral precision, downstream TAT
A8: H4 | B8: Intelligent Rule Engine & Decision Automation | C8: — | D8: High | E8: High | F8: — | G8: — | H8: — | I8: Auto-decision rate, override rate, decision TAT, leakage
A9: H5 | B9: AI Portfolio-Level Claims Intelligence & Provider Analytics | C9: — | D9: High | E9: Medium | F9: — | G9: — | H9: High | I9: Cost per episode vs benchmark, provider score adoption, leakage identified
A10: H6 | B10: GTM (Go-To-Market) Rollout | C10: — | D10: — | E10: Medium | F10: — | G10: — | H10: — | I10: Go-live milestones met, adoption rate, incident rate post-launch
A11: H7 | B11: MVP 2 — Expanded Health AI Capabilities | C11: — | D11: High | E11: High | F11: — | G11: — | H11: — | I11: Scope-expansion milestones, incremental STP/fraud KPIs vs MVP1 baseline
A12: O1 | B12: Ingest, Extract & Summarize Medical Information (Life & Health) | C12: — | D12: — | E12: — | F12: — | G12: — | H12: — | I12: Extraction accuracy, docs auto-processed %, re-key effort saved
A13: O2 | B13: Structure Unstructured Data for Underwriting | C13: — | D13: — | E13: High | F13: — | G13: — | H13: — | I13: Profile completeness, extraction accuracy, UW prep time
A14: O2B | B14: Automated KYC Verification | C14: — | D14: — | E14: High | F14: — | G14: — | H14: — | I14: Onboarding TAT, KYC exception rate, compliance findings
A15: O3 | B15: GenAI Proactive Data-Quality Detection | C15: — | D15: — | E15: — | F15: — | G15: — | H15: — | I15: DQ score trend, duplicate rate, issues auto-detected %
... A50: A21 | B50: Action-Oriented Real-Time Performance Monitoring | C50: — | D50: — | E50: High | F50: — | G50: High | H50: — | I50: Intervention success rate, coached-cohort productivity delta, active-agent ratio

Sheet Industry Benchmark
A1: Industry Benchmark — Pan-Asian & Global Insurers (public information, researched Aug 2026)
A2: Based on public announcements, annual reports and press coverage as of Aug 2026; maturity ratings are directional analyst judgements, not audited scores.
A4: Company | B4: Current AI Investments | C4: Publicly Announced Capabilities | D4: GenAI Maturity | E4: Claims AI | F4: Underwriting AI | G4: Agent AI | H4: Customer AI | I4: Responsible AI Initiatives | J4: Relative Maturity | K4: Key Public Sources (2025-26)
A5: Prudential (plc) | B5: AI a core growth lever across Asia/Africa; GenAI platforms for distribution and health; agentic AI pilots (concierge scheduling); US affiliate reports 260+ active AI use cases | C5: PruAction GenAI agent performance-management platform launched in Singapore with multi-market rollout planned; 'Just Ask' AI underwriting assistant for advisors; AI health & claims initiatives | D5: High — GenAI embedded in agency management and advisor tooling; agentic pilots underway | E5: Medium-High — claims automation and EvolutionIQ-style claims optimization partnerships | F5: High — accelerated/automated underwriting, AI UW assistants, multi-test validation approach | G5: High — PruAction coaching, PRUVenture recruitment, advisor copilots | H5: High — engagement, health propositions, conversational service | I5: Human-centred AI positioning; governance and validation testing of AI outputs | J5: High | K5: Prudential plc FY2025 report; news.prudential.com (May 2026); fintech.global (May 2026); Computer Weekly
A6: AIA | B6: Sustained investment in AI underwriting/claims transformation and digital health; insurtech partnerships (Qumata, AiDa, Vymo, WhiteCoat) | C6: AI-powered pre-underwriting broadening insurable pool (Celent-recognised); claims automation; AIA Vitality wellness data flywheel; GenAI sales coaching and lead prioritisation for agents | D6: High — GenAI coaching and servicing tools scaling on top of mature predictive base | E6: High — claims transformation recognised industry-wide | F6: High — CI pre-underwriting and automated UW at scale | G6: High — agent productivity tooling, lead prioritisation, 24/7 coaching | H6: High — wellness-led engagement via Vitality ecosystem | I6: Responsible AI within group digital governance; wellness data consent frameworks | J6: High | K6: Celent case study; ResearchAndMarkets AIA Enterprise Tech 2025; MatrixBCG analysis (2026)
A7: Manulife | B7: US$1B+ enterprise AI value target by 2027 (US$300M realised by end-2025); 5-year expanded Microsoft partnership; Copilot for 30,000+ staff; Agent 365 governance control plane | C7: ChatMFC internal GenAI assistant; John Hancock 'Quick Quote' GenAI underwriting tool; GenAI supporting 110M+ service calls/yr; agentic workflows in production; 30% developer productivity via GitHub Copilot | D7: High — enterprise-wide GenAI with explicit ROI tracking and agent governance layer | E7: Medium-High — claims/service automation scaling across NA and Asia | F7: High — Quick Quote GenAI UW support live in market | G7: Medium-High — advisor enablement expanding; strongest in employee/service AI | H7: High — call-centre GenAI with source-backed answers and confidence scores | I7: First large deployment of Microsoft Agent 365 governance; AI Community of Practice (~5,000 staff); exec AI training | J7: High | K7: Manulife–Microsoft release (Jul 2026); Digital Insurance (Jun 2026)
A8: Sun Life | B8: US$1.2B+/yr digital transformation spend; enterprise GenAI platform; 2026-2028 digital & tech strategy centred on advisors, modern practice, embedded AI governance | C8: 'Sun Life Asks' internal GenAI (3M+ queries, ~20k weekly visits); advisor Notes Assistant; GenAI physician-statement summarisation for UW (exploration); AI-driven UW cutting standard policy issuance from days to minutes; Lumino Health AI navigation | D8: Medium-High — strong internal scale; customer-facing GenAI deployed cautiously | E8: Medium — established predictive models in claims/risk | F8: Medium-High — accelerated UW plus GenAI evidence summarisation pilots | G8: Medium-High — advisor meeting-note and productivity tools in Canada/Asia | H8: Medium-High — proactive engagement to 30M+ clients; HK Gen A.I. Sandbox++ participation | I8: Named Responsible AI framework; 'governance by design' from experiment to production; continuous testing for agentic AI | J8: Medium-High | K8: CDO Magazine (Dec 2025); sunlife.com Responsible AI; SCMP (May 2026); MatrixBCG (2026)
A9: Allianz | B9: Ranked #1 of 30 insurers in 2026 Evident AI Index; largest AI talent pool in industry (~28% larger than AXA); global Anthropic partnership (workforce, agentic operations, compliance) | C9: AllianzGPT enterprise assistant; Insurance Copilot for claims (live since 2024); Project Nemo multi-agent food-spoilage claims (~80% faster, human-in-the-loop); BRIAN RAG assistant for P&C/Specialty underwriters | D9: High — market-leading; agentic claims in production plus enterprise GenAI platform | E9: High — Copilot + agentic claims automation in production | F9: High — BRIAN RAG over UW guides in full production | G9: Medium — focus more on employee/underwriter than tied-agent tooling | H9: Medium-High — service automation and prevention propositions | I9: Safety-first Anthropic partnership framing; human-in-the-loop mandated in agentic claims; large AI upskilling programs | J9: Very High (Evident #1, 2026) | K9: Evident AI Index 2026; allianz.com AI hub; Insurance Business (Jun 2026); InsureBench
A10: AXA | B10: AI-at-scale strategy; Secure GPT live 3 years for 140,000 employees; global Microsoft 365 Copilot rollout announced Jul 2026; long-time Evident leader (recently overtaken by Allianz) | C10: Secure GPT enterprise LLM platform (text, summarisation, translation, code); RAG underwriting-guidance pilot cut guide lookup from ~10 min to <3 min with 86% strong user ratings; deliberate, governance-first scaling | D10: High — early enterprise GenAI mover; measured production scaling | E10: Medium-High — claims automation mature in motor/health across entities | F10: High — RAG UW guidance and decision support scaling | G10: Medium — agent/advisor tooling less publicised than employee platform | H10: Medium-High — service and engagement AI across markets | I10: Responsible AI and employee-dialogue approach to AI deployment; data-privacy-first Secure GPT design | J10: High (Evident #2, 2026) | K10: axa.com press (Jul 2026); Computing.co.uk (Feb 2026); Digital Insurer case study; Evident Index 2026
A11: Ping An | B11: 'AI in All' strategy; decade-plus of AI R&D; among world's largest insurance AI patent holders; showcased healthcare/insurance/payments AI at WAIC 2026 | C11: P&C: 100% AI coverage of core business scenarios, ~80% operational efficiency gain claimed; 93% of new vehicle policies auto-issued (6 min → 1.2 min); EagleX risk platform (100+ risk models); AI Family Doctor with 90M MAU; disease-specific AI product portfolio | D11: Very High — deepest end-to-end deployment among peers; proprietary model stack | E11: Very High — image-based assessment, auto-issuance and STP claims at national scale | F11: High — automated UW embedded across P&C and life | G11: High — AskBob-style agent assistants and AI-driven agent management | H11: Very High — AI Family Doctor, service robots covering vast majority of service volume | I11: In-house AI ethics/governance framework; regulatory alignment in China; risk-prevention (EagleX) positioning | J11: Very High | K11: Ping An Group / PRNewswire WAIC 2026 release (Jul 2026)

Sheet Implementation Roadmap
A1: Implementation Roadmap — Quick Wins → Phase 3
A4: Phase | B4: ID | C4: Initiative | D4: Domain | E4: Est. Complexity | F4: Complexity Score (1-5) | G4: Est. Business Value | H4: Value Score (1-5) | I4: Indicative Timing | J4: Rationale / Dependencies
A5: Quick Win (0-6 months) — 13 initiatives — Low complexity, proven tech, fast payback; builds momentum and funds the journey
A6: Quick Win | B6: O1 | C6: Ingest, Extract & Summarize Medical Information (Life & Health) | D6: Operations | E6: Low-Medium | F6: 2 | G6: High | H6: 4 | I6: 0-6 months | J6: Maturity: High. Value driver: Shared extraction service feeding UW and claims
A7: Quick Win | B7: O2 | C7: Structure Unstructured Data for Underwriting | D7: Operations | E7: Medium | F7: 3 | G7: High | H7: 4 | I7: 0-6 months | J7: Maturity: High. Value driver: Feeds indicative UW decisions (O4) and pricing (O8)
A8: Quick Win | B8: O2B | C8: Automated KYC Verification | D8: Operations | E8: Low | F8: 2 | G8: Medium | H8: 3 | I8: 0-6 months | J8: Maturity: High. Value driver: Faster onboarding with lower compliance risk
A9: Quick Win | B9: O3 | C9: GenAI Proactive Data-Quality Detection | D9: Operations | E9: Low-Medium | F9: 2 | G9: Medium | H9: 3 | I9: 0-6 months | J9: Maturity: Medium. Value driver: Foundation multiplier for every other initiative
A10: Quick Win | B10: O6 | C10: Helpdesk Chatbot for Agents / Banca RMs | D10: Operations | E10: Low | F10: 2 | G10: Medium | H10: 3 | I10: 0-6 months | J10: Maturity: High. Value driver: Sun Life Asks-style internal productivity at scale
A11: Quick Win | B11: A3 | C11: Pre-Sales Intelligence Engine | D11: Agency | E11: Low-Medium | F11: 2 | G11: High | H11: 4 | I11: 0-6 months | J11: Maturity: Medium-High. Value driver: Better conversations, higher conversion
A12: Quick Win | B12: A5 | C12: Investment Earning Simulator | D12: Agency | E12: Low-Medium | F12: 2 | G12: Medium | H12: 3 | I12: 0-6 months | J12: Maturity: Medium-High. Value driver: Clearer value stories accelerate closing
A13: Quick Win | B13: A6 | C13: AI "Get Smart" / Pre-Pitch Support | D13: Agency | E13: Low-Medium | F13: 2 | G13: Medium | H13: 3 | I13: 0-6 months | J13: Maturity: Medium. Value driver: Raises average pitch to top-quartile standard
A14: Quick Win | B14: A7 | C14: Value-Based Segmentation & Prioritization | D14: Agency | E14: Low-Medium | F14: 2 | G14: Medium | H14: 3 | I14: 0-6 months | J14: Maturity: High. Value driver: Focuses force effort where value is
A15: Quick Win | B15: A11 | C15: AI Nudges for Agents (Key Actions) | D15: Agency | E15: Low | F15: 1 | G15: Medium | H15: 3 | I15: 0-6 months | J15: Maturity: High. Value driver: Low-cost, high-frequency productivity gain
A16: Quick Win | B16: A13 | C16: AI-Enabled Agent Profiling | D16: Agency | E16: Low-Medium | F16: 2 | G16: Medium | H16: 3 | I16: 0-6 months | J16: Maturity: Medium-High. Value driver: Foundation for coaching, training and nudges
A17: Quick Win | B17: A15 | C17: AI Nudges for Agents (Productivity) | D17: Agency | E17: Low | F17: 1 | G17: Medium | H17: 3 | I17: 0-6 months | J17: Maturity: Medium-High. Value driver: Compounding micro-gains across the force
A18: Quick Win | B18: A20 | C18: Real-Time Performance Monitoring for Leaders | D18: Agency | E18: Low-Medium | F18: 2 | G18: Medium | H18: 3 | I18: 0-6 months | J18: Maturity: Medium-High. Value driver: From retrospective reporting to live steering
A19: Phase 1 (6-18 months) — 20 initiatives — Core value engines on strengthened data foundations (Customer 360, document AI platform, RAG stack)
A20: Phase 1 | B20: H1 | C20: AI-Powered Document Digitization | D20: Health | E20: Medium | F20: 3 | G20: Very High | H20: 5 | I20: 6-18 months | J20: Maturity: High (widely adopted). Value driver: Faster processing and reduced manual effort across UW and claims
A21: Phase 1 | B21: H2 | C21: GenAI Real-Time FWA Detection | D21: Health | E21: High | F21: 4 | G21: Very High | H21: 5 | I21: 6-18 months | J21: Maturity: Medium-High. Value driver: Direct claims-cost avoidance and loss-ratio improvement
A22: Phase 1 | B22: H3 | C22: ML-Powered Predictive Risk Scoring | D22: Health | E22: Medium | F22: 3 | G22: High | H22: 4 | I22: 6-18 months | J22: Maturity: High. Value driver: Consistent risk selection and faster decisions
A23: Phase 1 | B23: H4 | C23: Intelligent Rule Engine & Decision Automation | D23: Health | E23: Medium-High | F23: 4 | G23: Very High | H23: 5 | I23: 6-18 months | J23: Maturity: High. Value driver: Straight-through decisions with human-in-the-loop for exceptions
A24: Phase 1 | B24: H5 | C24: AI Portfolio-Level Claims Intelligence & Provider Analytics | D24: Health | E24: Medium | F24: 3 | G24: High | H24: 4 | I24: 6-18 months | J24: Maturity: Medium-High. Value driver: Better provider negotiation and network steering
A25: Phase 1 | B25: H6 | C25: GTM (Go-To-Market) Rollout | D25: Health | E25: Medium | F25: 3 | G25: Medium | H25: 3 | I25: 6-18 months | J25: Maturity: N/A (program phase). Value driver: Converts Health AI builds into realised business value
A26: Phase 1 | B26: O4 | C26: Generate Indicative Decisions for Underwriters | D26: Operations | E26: High | F26: 4 | G26: Very High | H26: 5 | I26: 6-18 months | J26: Maturity: High. Value driver: Higher STP issuance and capacity uplift
A27: Phase 1 | B27: O5 | C27: Generate Indicative Decisions for Agents / Banca RMs | D27: Operations | E27: Medium | F27: 3 | G27: High | H27: 4 | I27: 6-18 months | J27: Maturity: High. Value driver: Bridges Operations data into Agency selling motion
A28: Phase 1 | B28: O9 | C28: Proactive Renewals | D28: Operations | E28: Low-Medium | F28: 2 | G28: Very High | H28: 5 | I28: 6-18 months | J28: Maturity: High. Value driver: Direct revenue retention
A29: Phase 1 | B29: O11 | C29: Customer Self-Service Assistant (Chatbot) | D29: Operations | E29: Medium | F29: 3 | G29: High | H29: 4 | I29: 6-18 months | J29: Maturity: High. Value driver: Contact-centre cost reduction and 24/7 service
A30: Phase 1 | B30: O12 | C30: Smart Routing | D30: Operations | E30: Medium | F30: 3 | G30: Medium | H30: 3 | I30: 6-18 months | J30: Maturity: Medium-High. Value driver: Throughput and SLA stability
A31: Phase 1 | B31: O14 | C31: Servicing Staff Support AI | D31: Operations | E31: Medium | F31: 3 | G31: High | H31: 4 | I31: 6-18 months | J31: Maturity: High. Value driver: Manulife-style copilot productivity across servicing
... A39: Phase 1 | B39: A21 | C39: Action-Oriented Real-Time Performance Monitoring | D39: Agency | E39: Medium | F39: 3 | G39: High | H39: 4 | I39: 6-18 months | J39: Maturity: Medium-High. Value driver: Prudential PruAction benchmark: GenAI performance management
A40: Phase 2 (18-30 months) — 9 initiatives — Advanced analytics needing richer data/graph foundations and change management
A41: Phase 2 | B41: H7 | C41: MVP 2 — Expanded Health AI Capabilities | D41: Health | E41: Medium-High | F41: 4 | G41: Medium | H41: 3 | I41: 18-30 months | J41: Maturity: N/A (program phase). Value driver: Compounding value on the MVP foundation
A42: Phase 2 | B42: O7 | C42: Identify High-Value Distribution Partners / Clients / Cases | D42: Operations | E42: Medium | F42: 3 | G42: Medium | H42: 3 | I42: 18-30 months | J42: Maturity: Medium. Value driver: Better network economics and partner steering
A43: Phase 2 | B43: O8 | C43: Technical Pricing | D43: Operations | E43: High | F43: 4 | G43: High | H43: 4 | I43: 18-30 months | J43: Maturity: Medium-High. Value driver: Margin protection with competitive positioning
A44: Phase 2 | B44: O13 | C44: GenAI Real-Time Coaching | D44: Operations | E44: Medium-High | F44: 4 | G44: Medium | H44: 3 | I44: 18-30 months | J44: Maturity: Medium-High. Value driver: Quality uplift on 100% of interactions
A45: Phase 2 | B45: O16 | C45: AI-Enabled Claims Adjudication | D45: Operations | E45: High | F45: 5 | G45: Very High | H45: 5 | I45: 18-30 months | J45: Maturity: High. Value driver: Flagship cost and CX initiative (Ping An/Allianz benchmark)
A46: Phase 2 | B46: A9 | C46: Proactive Servicing & Admin Automation AI | D46: Agency | E46: Medium | F46: 3 | G46: High | H46: 4 | I46: 18-30 months | J46: Maturity: Medium-High. Value driver: Retention and experience uplift
